[2025-05-19T07:25:22.610+0000] {local_task_job_runner.py:120} INFO - ::group::Pre task execution logs
[2025-05-19T07:25:22.644+0000] {taskinstance.py:2076} INFO - Dependencies all met for dep_context=non-requeueable deps ti=<TaskInstance: flight_price_pipeline.load_to_postgres manual__2025-05-19T07:23:54.525838+00:00 [queued]>
[2025-05-19T07:25:22.651+0000] {taskinstance.py:2076} INFO - Dependencies all met for dep_context=requeueable deps ti=<TaskInstance: flight_price_pipeline.load_to_postgres manual__2025-05-19T07:23:54.525838+00:00 [queued]>
[2025-05-19T07:25:22.651+0000] {taskinstance.py:2306} INFO - Starting attempt 2 of 3
[2025-05-19T07:25:22.660+0000] {taskinstance.py:2330} INFO - Executing <Task(PythonOperator): load_to_postgres> on 2025-05-19 07:23:54.525838+00:00
[2025-05-19T07:25:22.672+0000] {standard_task_runner.py:90} INFO - Running: ['***', 'tasks', 'run', 'flight_price_pipeline', 'load_to_postgres', 'manual__2025-05-19T07:23:54.525838+00:00', '--job-id', '6', '--raw', '--subdir', 'DAGS_FOLDER/flight_price_pipeline.py', '--cfg-path', '/tmp/tmp334s7zk5']
[2025-05-19T07:25:22.676+0000] {logging_mixin.py:188} WARNING - /home/***/.local/lib/python3.12/site-packages/***/task/task_runner/standard_task_runner.py:62 DeprecationWarning: This process (pid=228) is multi-threaded, use of fork() may lead to deadlocks in the child.
[2025-05-19T07:25:22.677+0000] {standard_task_runner.py:91} INFO - Job 6: Subtask load_to_postgres
[2025-05-19T07:25:22.677+0000] {standard_task_runner.py:64} INFO - Started process 230 to run task
[2025-05-19T07:25:22.727+0000] {task_command.py:426} INFO - Running <TaskInstance: flight_price_pipeline.load_to_postgres manual__2025-05-19T07:23:54.525838+00:00 [running]> on host 76113153f3f2
[2025-05-19T07:25:23.528+0000] {taskinstance.py:2648} INFO - Exporting env vars: AIRFLOW_CTX_DAG_OWNER='***' AIRFLOW_CTX_DAG_ID='flight_price_pipeline' AIRFLOW_CTX_TASK_ID='load_to_postgres' AIRFLOW_CTX_EXECUTION_DATE='2025-05-19T07:23:54.525838+00:00' AIRFLOW_CTX_TRY_NUMBER='2' AIRFLOW_CTX_DAG_RUN_ID='manual__2025-05-19T07:23:54.525838+00:00'
[2025-05-19T07:25:23.529+0000] {taskinstance.py:430} INFO - ::endgroup::
[2025-05-19T07:25:23.538+0000] {loading.py:35} INFO - Starting data loading from MYSQL table flight_prices_raw_transformed to PostgreSQL
[2025-05-19T07:25:23.876+0000] {loading.py:62} ERROR - Failed to load data from MySQL to PostgreSQL: Table Select * from flight_prices_raw_transformed not found
[2025-05-19T07:25:23.879+0000] {taskinstance.py:441} INFO - ::group::Post task execution logs
[2025-05-19T07:25:23.881+0000] {taskinstance.py:2905} ERROR - Task failed with exception
Traceback (most recent call last):
  File "/home/airflow/.local/lib/python3.12/site-packages/airflow/models/taskinstance.py", line 465, in _execute_task
    result = _execute_callable(context=context, **execute_callable_kwargs)
             ^^^^^^^^^^^^^^^^^^^^^^^^^^^^^^^^^^^^^^^^^^^^^^^^^^^^^^^^^^^^^
  File "/home/airflow/.local/lib/python3.12/site-packages/airflow/models/taskinstance.py", line 432, in _execute_callable
    return execute_callable(context=context, **execute_callable_kwargs)
           ^^^^^^^^^^^^^^^^^^^^^^^^^^^^^^^^^^^^^^^^^^^^^^^^^^^^^^^^^^^^
  File "/home/airflow/.local/lib/python3.12/site-packages/airflow/models/baseoperator.py", line 401, in wrapper
    return func(self, *args, **kwargs)
           ^^^^^^^^^^^^^^^^^^^^^^^^^^^
  File "/home/airflow/.local/lib/python3.12/site-packages/airflow/operators/python.py", line 235, in execute
    return_value = self.execute_callable()
                   ^^^^^^^^^^^^^^^^^^^^^^^
  File "/home/airflow/.local/lib/python3.12/site-packages/airflow/operators/python.py", line 252, in execute_callable
    return self.python_callable(*self.op_args, **self.op_kwargs)
           ^^^^^^^^^^^^^^^^^^^^^^^^^^^^^^^^^^^^^^^^^^^^^^^^^^^^^
  File "/opt/airflow/dags/scripts/loading.py", line 58, in load_to_postgres
    df = pd.read_sql_table(f"Select * from {mysql_table}", con=mysql_engine)
         ^^^^^^^^^^^^^^^^^^^^^^^^^^^^^^^^^^^^^^^^^^^^^^^^^^^^^^^^^^^^^^^^^^^
  File "/home/airflow/.local/lib/python3.12/site-packages/pandas/io/sql.py", line 346, in read_sql_table
    raise ValueError(f"Table {table_name} not found")
ValueError: Table Select * from flight_prices_raw_transformed not found
[2025-05-19T07:25:23.929+0000] {taskinstance.py:1206} INFO - Marking task as UP_FOR_RETRY. dag_id=flight_price_pipeline, task_id=load_to_postgres, run_id=manual__2025-05-19T07:23:54.525838+00:00, execution_date=20250519T072354, start_date=20250519T072522, end_date=20250519T072523
[2025-05-19T07:25:23.975+0000] {standard_task_runner.py:110} ERROR - Failed to execute job 6 for task load_to_postgres (Table Select * from flight_prices_raw_transformed not found; 230)
[2025-05-19T07:25:24.070+0000] {local_task_job_runner.py:243} INFO - Task exited with return code 1
[2025-05-19T07:25:24.133+0000] {taskinstance.py:3503} INFO - 0 downstream tasks scheduled from follow-on schedule check
[2025-05-19T07:25:24.136+0000] {local_task_job_runner.py:222} INFO - ::endgroup::
