[2025-05-19T06:56:49.162+0000] {local_task_job_runner.py:120} INFO - ::group::Pre task execution logs
[2025-05-19T06:56:49.257+0000] {taskinstance.py:2076} INFO - Dependencies all met for dep_context=non-requeueable deps ti=<TaskInstance: flight_price_pipeline.transform_and_compute_kpis manual__2025-05-19T06:55:32.377953+00:00 [queued]>
[2025-05-19T06:56:49.270+0000] {taskinstance.py:2076} INFO - Dependencies all met for dep_context=requeueable deps ti=<TaskInstance: flight_price_pipeline.transform_and_compute_kpis manual__2025-05-19T06:55:32.377953+00:00 [queued]>
[2025-05-19T06:56:49.271+0000] {taskinstance.py:2306} INFO - Starting attempt 1 of 3
[2025-05-19T06:56:49.287+0000] {taskinstance.py:2330} INFO - Executing <Task(PythonOperator): transform_and_compute_kpis> on 2025-05-19 06:55:32.377953+00:00
[2025-05-19T06:56:49.338+0000] {logging_mixin.py:188} WARNING - /home/***/.local/lib/python3.12/site-packages/***/task/task_runner/standard_task_runner.py:62 DeprecationWarning: This process (pid=253) is multi-threaded, use of fork() may lead to deadlocks in the child.
[2025-05-19T06:56:49.340+0000] {standard_task_runner.py:64} INFO - Started process 255 to run task
[2025-05-19T06:56:49.336+0000] {standard_task_runner.py:90} INFO - Running: ['***', 'tasks', 'run', 'flight_price_pipeline', 'transform_and_compute_kpis', 'manual__2025-05-19T06:55:32.377953+00:00', '--job-id', '10', '--raw', '--subdir', 'DAGS_FOLDER/flight_price_pipeline.py', '--cfg-path', '/tmp/tmp7teb6unm']
[2025-05-19T06:56:49.343+0000] {standard_task_runner.py:91} INFO - Job 10: Subtask transform_and_compute_kpis
[2025-05-19T06:56:49.433+0000] {task_command.py:426} INFO - Running <TaskInstance: flight_price_pipeline.transform_and_compute_kpis manual__2025-05-19T06:55:32.377953+00:00 [running]> on host fe3eaa227362
[2025-05-19T06:56:49.525+0000] {taskinstance.py:2648} INFO - Exporting env vars: AIRFLOW_CTX_DAG_OWNER='***' AIRFLOW_CTX_DAG_ID='flight_price_pipeline' AIRFLOW_CTX_TASK_ID='transform_and_compute_kpis' AIRFLOW_CTX_EXECUTION_DATE='2025-05-19T06:55:32.377953+00:00' AIRFLOW_CTX_TRY_NUMBER='1' AIRFLOW_CTX_DAG_RUN_ID='manual__2025-05-19T06:55:32.377953+00:00'
[2025-05-19T06:56:49.527+0000] {taskinstance.py:430} INFO - ::endgroup::
[2025-05-19T06:56:49.544+0000] {transformation.py:36} INFO - Starting transformation and KPI computation for table flight_prices_raw
[2025-05-19T06:56:50.256+0000] {transformation.py:50} ERROR - Failed to read data from MySQL Table Select * from flight_prices_raw not found
[2025-05-19T06:56:50.256+0000] {taskinstance.py:441} INFO - ::group::Post task execution logs
[2025-05-19T06:56:50.257+0000] {taskinstance.py:2905} ERROR - Task failed with exception
Traceback (most recent call last):
  File "/home/airflow/.local/lib/python3.12/site-packages/airflow/models/taskinstance.py", line 465, in _execute_task
    result = _execute_callable(context=context, **execute_callable_kwargs)
             ^^^^^^^^^^^^^^^^^^^^^^^^^^^^^^^^^^^^^^^^^^^^^^^^^^^^^^^^^^^^^
  File "/home/airflow/.local/lib/python3.12/site-packages/airflow/models/taskinstance.py", line 432, in _execute_callable
    return execute_callable(context=context, **execute_callable_kwargs)
           ^^^^^^^^^^^^^^^^^^^^^^^^^^^^^^^^^^^^^^^^^^^^^^^^^^^^^^^^^^^^
  File "/home/airflow/.local/lib/python3.12/site-packages/airflow/models/baseoperator.py", line 401, in wrapper
    return func(self, *args, **kwargs)
           ^^^^^^^^^^^^^^^^^^^^^^^^^^^
  File "/home/airflow/.local/lib/python3.12/site-packages/airflow/operators/python.py", line 235, in execute
    return_value = self.execute_callable()
                   ^^^^^^^^^^^^^^^^^^^^^^^
  File "/home/airflow/.local/lib/python3.12/site-packages/airflow/operators/python.py", line 252, in execute_callable
    return self.python_callable(*self.op_args, **self.op_kwargs)
           ^^^^^^^^^^^^^^^^^^^^^^^^^^^^^^^^^^^^^^^^^^^^^^^^^^^^^
  File "/opt/airflow/dags/scripts/transformation.py", line 47, in transform_and_compute_kpis
    df = pd.read_sql_table(f"Select * from {table_name}", con=engine)
         ^^^^^^^^^^^^^^^^^^^^^^^^^^^^^^^^^^^^^^^^^^^^^^^^^^^^^^^^^^^^
  File "/home/airflow/.local/lib/python3.12/site-packages/pandas/io/sql.py", line 346, in read_sql_table
    raise ValueError(f"Table {table_name} not found")
ValueError: Table Select * from flight_prices_raw not found
[2025-05-19T06:56:50.294+0000] {taskinstance.py:1206} INFO - Marking task as UP_FOR_RETRY. dag_id=flight_price_pipeline, task_id=transform_and_compute_kpis, run_id=manual__2025-05-19T06:55:32.377953+00:00, execution_date=20250519T065532, start_date=20250519T065649, end_date=20250519T065650
[2025-05-19T06:56:50.313+0000] {standard_task_runner.py:110} ERROR - Failed to execute job 10 for task transform_and_compute_kpis (Table Select * from flight_prices_raw not found; 255)
[2025-05-19T06:56:50.353+0000] {local_task_job_runner.py:243} INFO - Task exited with return code 1
[2025-05-19T06:56:50.387+0000] {taskinstance.py:3503} INFO - 0 downstream tasks scheduled from follow-on schedule check
[2025-05-19T06:56:50.389+0000] {local_task_job_runner.py:222} INFO - ::endgroup::
