[2025-05-19T06:58:55.235+0000] {local_task_job_runner.py:120} INFO - ::group::Pre task execution logs
[2025-05-19T06:58:55.367+0000] {taskinstance.py:2076} INFO - Dependencies all met for dep_context=non-requeueable deps ti=<TaskInstance: flight_price_pipeline.transform_and_compute_kpis manual__2025-05-19T06:55:32.377953+00:00 [queued]>
[2025-05-19T06:58:55.398+0000] {taskinstance.py:2076} INFO - Dependencies all met for dep_context=requeueable deps ti=<TaskInstance: flight_price_pipeline.transform_and_compute_kpis manual__2025-05-19T06:55:32.377953+00:00 [queued]>
[2025-05-19T06:58:55.399+0000] {taskinstance.py:2306} INFO - Starting attempt 3 of 3
[2025-05-19T06:58:55.423+0000] {taskinstance.py:2330} INFO - Executing <Task(PythonOperator): transform_and_compute_kpis> on 2025-05-19 06:55:32.377953+00:00
[2025-05-19T06:58:55.475+0000] {logging_mixin.py:188} WARNING - /home/***/.local/lib/python3.12/site-packages/***/task/task_runner/standard_task_runner.py:62 DeprecationWarning: This process (pid=283) is multi-threaded, use of fork() may lead to deadlocks in the child.
[2025-05-19T06:58:55.456+0000] {standard_task_runner.py:90} INFO - Running: ['***', 'tasks', 'run', 'flight_price_pipeline', 'transform_and_compute_kpis', 'manual__2025-05-19T06:55:32.377953+00:00', '--job-id', '12', '--raw', '--subdir', 'DAGS_FOLDER/flight_price_pipeline.py', '--cfg-path', '/tmp/tmppsxmczg5']
[2025-05-19T06:58:55.477+0000] {standard_task_runner.py:91} INFO - Job 12: Subtask transform_and_compute_kpis
[2025-05-19T06:58:55.476+0000] {standard_task_runner.py:64} INFO - Started process 285 to run task
[2025-05-19T06:58:55.574+0000] {task_command.py:426} INFO - Running <TaskInstance: flight_price_pipeline.transform_and_compute_kpis manual__2025-05-19T06:55:32.377953+00:00 [running]> on host fe3eaa227362
[2025-05-19T06:58:55.789+0000] {taskinstance.py:2648} INFO - Exporting env vars: AIRFLOW_CTX_DAG_OWNER='***' AIRFLOW_CTX_DAG_ID='flight_price_pipeline' AIRFLOW_CTX_TASK_ID='transform_and_compute_kpis' AIRFLOW_CTX_EXECUTION_DATE='2025-05-19T06:55:32.377953+00:00' AIRFLOW_CTX_TRY_NUMBER='3' AIRFLOW_CTX_DAG_RUN_ID='manual__2025-05-19T06:55:32.377953+00:00'
[2025-05-19T06:58:55.799+0000] {taskinstance.py:430} INFO - ::endgroup::
[2025-05-19T06:58:55.860+0000] {transformation.py:36} INFO - Starting transformation and KPI computation for table flight_prices_raw
[2025-05-19T06:58:57.659+0000] {transformation.py:50} ERROR - Failed to read data from MySQL Table Select * from flight_prices_raw not found
[2025-05-19T06:58:57.662+0000] {taskinstance.py:441} INFO - ::group::Post task execution logs
[2025-05-19T06:58:57.664+0000] {taskinstance.py:2905} ERROR - Task failed with exception
Traceback (most recent call last):
  File "/home/airflow/.local/lib/python3.12/site-packages/airflow/models/taskinstance.py", line 465, in _execute_task
    result = _execute_callable(context=context, **execute_callable_kwargs)
             ^^^^^^^^^^^^^^^^^^^^^^^^^^^^^^^^^^^^^^^^^^^^^^^^^^^^^^^^^^^^^
  File "/home/airflow/.local/lib/python3.12/site-packages/airflow/models/taskinstance.py", line 432, in _execute_callable
    return execute_callable(context=context, **execute_callable_kwargs)
           ^^^^^^^^^^^^^^^^^^^^^^^^^^^^^^^^^^^^^^^^^^^^^^^^^^^^^^^^^^^^
  File "/home/airflow/.local/lib/python3.12/site-packages/airflow/models/baseoperator.py", line 401, in wrapper
    return func(self, *args, **kwargs)
           ^^^^^^^^^^^^^^^^^^^^^^^^^^^
  File "/home/airflow/.local/lib/python3.12/site-packages/airflow/operators/python.py", line 235, in execute
    return_value = self.execute_callable()
                   ^^^^^^^^^^^^^^^^^^^^^^^
  File "/home/airflow/.local/lib/python3.12/site-packages/airflow/operators/python.py", line 252, in execute_callable
    return self.python_callable(*self.op_args, **self.op_kwargs)
           ^^^^^^^^^^^^^^^^^^^^^^^^^^^^^^^^^^^^^^^^^^^^^^^^^^^^^
  File "/opt/airflow/dags/scripts/transformation.py", line 47, in transform_and_compute_kpis
    df = pd.read_sql_table(f"Select * from {table_name}", con=engine)
         ^^^^^^^^^^^^^^^^^^^^^^^^^^^^^^^^^^^^^^^^^^^^^^^^^^^^^^^^^^^^
  File "/home/airflow/.local/lib/python3.12/site-packages/pandas/io/sql.py", line 346, in read_sql_table
    raise ValueError(f"Table {table_name} not found")
ValueError: Table Select * from flight_prices_raw not found
[2025-05-19T06:58:57.741+0000] {taskinstance.py:1206} INFO - Marking task as FAILED. dag_id=flight_price_pipeline, task_id=transform_and_compute_kpis, run_id=manual__2025-05-19T06:55:32.377953+00:00, execution_date=20250519T065532, start_date=20250519T065855, end_date=20250519T065857
[2025-05-19T06:58:57.762+0000] {standard_task_runner.py:110} ERROR - Failed to execute job 12 for task transform_and_compute_kpis (Table Select * from flight_prices_raw not found; 285)
[2025-05-19T06:58:57.814+0000] {local_task_job_runner.py:243} INFO - Task exited with return code 1
[2025-05-19T06:58:57.891+0000] {taskinstance.py:3503} INFO - 0 downstream tasks scheduled from follow-on schedule check
[2025-05-19T06:58:57.898+0000] {local_task_job_runner.py:222} INFO - ::endgroup::
