[2025-05-19T06:47:40.802+0000] {local_task_job_runner.py:120} INFO - ::group::Pre task execution logs
[2025-05-19T06:47:41.151+0000] {taskinstance.py:2076} INFO - Dependencies all met for dep_context=non-requeueable deps ti=<TaskInstance: flight_price_pipeline.transform_and_compute_kpis manual__2025-05-19T06:44:44.345225+00:00 [queued]>
[2025-05-19T06:47:41.197+0000] {taskinstance.py:2076} INFO - Dependencies all met for dep_context=requeueable deps ti=<TaskInstance: flight_price_pipeline.transform_and_compute_kpis manual__2025-05-19T06:44:44.345225+00:00 [queued]>
[2025-05-19T06:47:41.200+0000] {taskinstance.py:2306} INFO - Starting attempt 3 of 3
[2025-05-19T06:47:41.262+0000] {taskinstance.py:2330} INFO - Executing <Task(PythonOperator): transform_and_compute_kpis> on 2025-05-19 06:44:44.345225+00:00
[2025-05-19T06:47:41.391+0000] {standard_task_runner.py:90} INFO - Running: ['***', 'tasks', 'run', 'flight_price_pipeline', 'transform_and_compute_kpis', 'manual__2025-05-19T06:44:44.345225+00:00', '--job-id', '6', '--raw', '--subdir', 'DAGS_FOLDER/flight_price_pipeline.py', '--cfg-path', '/tmp/tmpv7p1k9xv']
[2025-05-19T06:47:41.405+0000] {logging_mixin.py:188} WARNING - /home/***/.local/lib/python3.12/site-packages/***/task/task_runner/standard_task_runner.py:62 DeprecationWarning: This process (pid=239) is multi-threaded, use of fork() may lead to deadlocks in the child.
[2025-05-19T06:47:41.406+0000] {standard_task_runner.py:64} INFO - Started process 243 to run task
[2025-05-19T06:47:41.405+0000] {standard_task_runner.py:91} INFO - Job 6: Subtask transform_and_compute_kpis
[2025-05-19T06:47:41.550+0000] {task_command.py:426} INFO - Running <TaskInstance: flight_price_pipeline.transform_and_compute_kpis manual__2025-05-19T06:44:44.345225+00:00 [running]> on host fb87d03914c7
[2025-05-19T06:47:41.771+0000] {taskinstance.py:2648} INFO - Exporting env vars: AIRFLOW_CTX_DAG_OWNER='***' AIRFLOW_CTX_DAG_ID='flight_price_pipeline' AIRFLOW_CTX_TASK_ID='transform_and_compute_kpis' AIRFLOW_CTX_EXECUTION_DATE='2025-05-19T06:44:44.345225+00:00' AIRFLOW_CTX_TRY_NUMBER='3' AIRFLOW_CTX_DAG_RUN_ID='manual__2025-05-19T06:44:44.345225+00:00'
[2025-05-19T06:47:41.789+0000] {taskinstance.py:430} INFO - ::endgroup::
[2025-05-19T06:47:41.981+0000] {transformation.py:36} INFO - Starting transformation and KPI computation for table flight_prices_raw
[2025-05-19T06:47:47.860+0000] {transformation.py:50} ERROR - Failed to read data from MySQL Table Select * from flight_prices_raw not found
[2025-05-19T06:47:47.869+0000] {taskinstance.py:441} INFO - ::group::Post task execution logs
[2025-05-19T06:47:47.880+0000] {taskinstance.py:2905} ERROR - Task failed with exception
Traceback (most recent call last):
  File "/home/airflow/.local/lib/python3.12/site-packages/airflow/models/taskinstance.py", line 465, in _execute_task
    result = _execute_callable(context=context, **execute_callable_kwargs)
             ^^^^^^^^^^^^^^^^^^^^^^^^^^^^^^^^^^^^^^^^^^^^^^^^^^^^^^^^^^^^^
  File "/home/airflow/.local/lib/python3.12/site-packages/airflow/models/taskinstance.py", line 432, in _execute_callable
    return execute_callable(context=context, **execute_callable_kwargs)
           ^^^^^^^^^^^^^^^^^^^^^^^^^^^^^^^^^^^^^^^^^^^^^^^^^^^^^^^^^^^^
  File "/home/airflow/.local/lib/python3.12/site-packages/airflow/models/baseoperator.py", line 401, in wrapper
    return func(self, *args, **kwargs)
           ^^^^^^^^^^^^^^^^^^^^^^^^^^^
  File "/home/airflow/.local/lib/python3.12/site-packages/airflow/operators/python.py", line 235, in execute
    return_value = self.execute_callable()
                   ^^^^^^^^^^^^^^^^^^^^^^^
  File "/home/airflow/.local/lib/python3.12/site-packages/airflow/operators/python.py", line 252, in execute_callable
    return self.python_callable(*self.op_args, **self.op_kwargs)
           ^^^^^^^^^^^^^^^^^^^^^^^^^^^^^^^^^^^^^^^^^^^^^^^^^^^^^
  File "/opt/airflow/dags/scripts/transformation.py", line 47, in transform_and_compute_kpis
    df = pd.read_sql_table(f"Select * from {table_name}", con=engine)
         ^^^^^^^^^^^^^^^^^^^^^^^^^^^^^^^^^^^^^^^^^^^^^^^^^^^^^^^^^^^^
  File "/home/airflow/.local/lib/python3.12/site-packages/pandas/io/sql.py", line 346, in read_sql_table
    raise ValueError(f"Table {table_name} not found")
ValueError: Table Select * from flight_prices_raw not found
[2025-05-19T06:47:48.087+0000] {taskinstance.py:1206} INFO - Marking task as FAILED. dag_id=flight_price_pipeline, task_id=transform_and_compute_kpis, run_id=manual__2025-05-19T06:44:44.345225+00:00, execution_date=20250519T064444, start_date=20250519T064741, end_date=20250519T064748
[2025-05-19T06:47:48.178+0000] {standard_task_runner.py:110} ERROR - Failed to execute job 6 for task transform_and_compute_kpis (Table Select * from flight_prices_raw not found; 243)
[2025-05-19T06:47:48.346+0000] {local_task_job_runner.py:243} INFO - Task exited with return code 1
[2025-05-19T06:47:48.517+0000] {taskinstance.py:3503} INFO - 0 downstream tasks scheduled from follow-on schedule check
[2025-05-19T06:47:48.519+0000] {local_task_job_runner.py:222} INFO - ::endgroup::
